[2023-01-16 15:56:05] [WARNING ] discord.client: PyNaCl is not installed, voice will NOT be supported
[2023-01-16 15:56:05] [INFO    ] discord.client: logging in using static token
[2023-01-16 15:56:06] [INFO    ] discord.gateway: Shard ID None has connected to Gateway (Session ID: 256c1cf89fa34eb9551044286d329449).
[2023-01-16 15:56:12] [ERROR   ] discord.client: Ignoring exception in on_message
Traceback (most recent call last):
  File "C:\Users\Hao Yan\AppData\Local\Programs\Python\Python310\lib\site-packages\discord\client.py", line 409, in _run_event
    await coro(*args, **kwargs)
  File "c:\Users\Hao Yan\Documents\GitHub\unnamed_bot\src\listener.py", line 35, in on_message
    await a_users_db(message.author)
  File "c:\Users\Hao Yan\Documents\GitHub\unnamed_bot\src\listener.py", line 17, in a_users_db
    with open('database/users.json', 'r') as f:
FileNotFoundError: [Errno 2] No such file or directory: 'database/users.json'
[2023-01-16 15:56:12] [ERROR   ] discord.ext.commands.bot: Ignoring exception in command botstats
Traceback (most recent call last):
  File "C:\Users\Hao Yan\AppData\Local\Programs\Python\Python310\lib\site-packages\discord\ext\commands\core.py", line 190, in wrapped
    ret = await coro(*args, **kwargs)
  File "c:\Users\Hao Yan\Documents\GitHub\unnamed_bot\src\admin.py", line 31, in botstats
    users = await a_users_db(ctx.author, action="v")
  File "c:\Users\Hao Yan\Documents\GitHub\unnamed_bot\src\admin.py", line 17, in a_users_db
    with open('database/users.json', 'r') as f:
FileNotFoundError: [Errno 2] No such file or directory: 'database/users.json'

The above exception was the direct cause of the following exception:

Traceback (most recent call last):
  File "C:\Users\Hao Yan\AppData\Local\Programs\Python\Python310\lib\site-packages\discord\ext\commands\bot.py", line 1347, in invoke
    await ctx.command.invoke(ctx)
  File "C:\Users\Hao Yan\AppData\Local\Programs\Python\Python310\lib\site-packages\discord\ext\commands\core.py", line 986, in invoke
    await injected(*ctx.args, **ctx.kwargs)  # type: ignore
  File "C:\Users\Hao Yan\AppData\Local\Programs\Python\Python310\lib\site-packages\discord\ext\commands\core.py", line 199, in wrapped
    raise CommandInvokeError(exc) from exc
discord.ext.commands.errors.CommandInvokeError: Command raised an exception: FileNotFoundError: [Errno 2] No such file or directory: 'database/users.json'
[2023-01-16 15:56:15] [ERROR   ] discord.client: Ignoring exception in on_message
Traceback (most recent call last):
  File "C:\Users\Hao Yan\AppData\Local\Programs\Python\Python310\lib\site-packages\discord\client.py", line 409, in _run_event
    await coro(*args, **kwargs)
  File "c:\Users\Hao Yan\Documents\GitHub\unnamed_bot\src\listener.py", line 35, in on_message
    await a_users_db(message.author)
  File "c:\Users\Hao Yan\Documents\GitHub\unnamed_bot\src\listener.py", line 17, in a_users_db
    with open('database/users.json', 'r') as f:
FileNotFoundError: [Errno 2] No such file or directory: 'database/users.json'
[2023-01-16 15:56:15] [ERROR   ] discord.ext.commands.bot: Ignoring exception in command botstats
Traceback (most recent call last):
  File "C:\Users\Hao Yan\AppData\Local\Programs\Python\Python310\lib\site-packages\discord\ext\commands\core.py", line 190, in wrapped
    ret = await coro(*args, **kwargs)
  File "c:\Users\Hao Yan\Documents\GitHub\unnamed_bot\src\admin.py", line 31, in botstats
    users = await a_users_db(ctx.author, action="v")
  File "c:\Users\Hao Yan\Documents\GitHub\unnamed_bot\src\admin.py", line 17, in a_users_db
    with open('database/users.json', 'r') as f:
FileNotFoundError: [Errno 2] No such file or directory: 'database/users.json'

The above exception was the direct cause of the following exception:

Traceback (most recent call last):
  File "C:\Users\Hao Yan\AppData\Local\Programs\Python\Python310\lib\site-packages\discord\ext\commands\bot.py", line 1347, in invoke
    await ctx.command.invoke(ctx)
  File "C:\Users\Hao Yan\AppData\Local\Programs\Python\Python310\lib\site-packages\discord\ext\commands\core.py", line 986, in invoke
    await injected(*ctx.args, **ctx.kwargs)  # type: ignore
  File "C:\Users\Hao Yan\AppData\Local\Programs\Python\Python310\lib\site-packages\discord\ext\commands\core.py", line 199, in wrapped
    raise CommandInvokeError(exc) from exc
discord.ext.commands.errors.CommandInvokeError: Command raised an exception: FileNotFoundError: [Errno 2] No such file or directory: 'database/users.json'
[2023-01-16 15:56:58] [WARNING ] discord.client: PyNaCl is not installed, voice will NOT be supported
[2023-01-16 15:56:58] [INFO    ] discord.client: logging in using static token
[2023-01-16 15:56:59] [INFO    ] discord.gateway: Shard ID None has connected to Gateway (Session ID: 0adfe06d9e4d97de036cbce735ae7ad8).
[2023-01-16 15:57:11] [ERROR   ] discord.ext.commands.bot: Ignoring exception in command botstats
Traceback (most recent call last):
  File "C:\Users\Hao Yan\AppData\Local\Programs\Python\Python310\lib\site-packages\discord\ext\commands\bot.py", line 1347, in invoke
    await ctx.command.invoke(ctx)
  File "C:\Users\Hao Yan\AppData\Local\Programs\Python\Python310\lib\site-packages\discord\ext\commands\core.py", line 978, in invoke
    await self.prepare(ctx)
  File "C:\Users\Hao Yan\AppData\Local\Programs\Python\Python310\lib\site-packages\discord\ext\commands\core.py", line 882, in prepare
    if not await self.can_run(ctx):
  File "C:\Users\Hao Yan\AppData\Local\Programs\Python\Python310\lib\site-packages\discord\ext\commands\core.py", line 1243, in can_run
    return await discord.utils.async_all(predicate(ctx) for predicate in predicates)
  File "C:\Users\Hao Yan\AppData\Local\Programs\Python\Python310\lib\site-packages\discord\utils.py", line 662, in async_all
    elem = await elem
  File "C:\Users\Hao Yan\AppData\Local\Programs\Python\Python310\lib\site-packages\discord\ext\commands\core.py", line 2327, in predicate
    raise NotOwner('You do not own this bot.')
discord.ext.commands.errors.NotOwner: You do not own this bot.
[2023-01-16 15:57:52] [ERROR   ] discord.ext.commands.bot: Ignoring exception in command botstats
Traceback (most recent call last):
  File "C:\Users\Hao Yan\AppData\Local\Programs\Python\Python310\lib\site-packages\discord\ext\commands\bot.py", line 1347, in invoke
    await ctx.command.invoke(ctx)
  File "C:\Users\Hao Yan\AppData\Local\Programs\Python\Python310\lib\site-packages\discord\ext\commands\core.py", line 978, in invoke
    await self.prepare(ctx)
  File "C:\Users\Hao Yan\AppData\Local\Programs\Python\Python310\lib\site-packages\discord\ext\commands\core.py", line 882, in prepare
    if not await self.can_run(ctx):
  File "C:\Users\Hao Yan\AppData\Local\Programs\Python\Python310\lib\site-packages\discord\ext\commands\core.py", line 1243, in can_run
    return await discord.utils.async_all(predicate(ctx) for predicate in predicates)
  File "C:\Users\Hao Yan\AppData\Local\Programs\Python\Python310\lib\site-packages\discord\utils.py", line 662, in async_all
    elem = await elem
  File "C:\Users\Hao Yan\AppData\Local\Programs\Python\Python310\lib\site-packages\discord\ext\commands\core.py", line 2327, in predicate
    raise NotOwner('You do not own this bot.')
discord.ext.commands.errors.NotOwner: You do not own this bot.
[2023-01-16 15:58:02] [ERROR   ] discord.ext.commands.bot: Ignoring exception in command None
discord.ext.commands.errors.CommandNotFound: Command "extensions" is not found
[2023-01-16 15:58:07] [ERROR   ] discord.ext.commands.bot: Ignoring exception in command None
discord.ext.commands.errors.CommandNotFound: Command "extensions" is not found
[2023-01-16 15:58:35] [ERROR   ] discord.ext.commands.bot: Ignoring exception in command botstats
Traceback (most recent call last):
  File "C:\Users\Hao Yan\AppData\Local\Programs\Python\Python310\lib\site-packages\discord\ext\commands\bot.py", line 1347, in invoke
    await ctx.command.invoke(ctx)
  File "C:\Users\Hao Yan\AppData\Local\Programs\Python\Python310\lib\site-packages\discord\ext\commands\core.py", line 978, in invoke
    await self.prepare(ctx)
  File "C:\Users\Hao Yan\AppData\Local\Programs\Python\Python310\lib\site-packages\discord\ext\commands\core.py", line 882, in prepare
    if not await self.can_run(ctx):
  File "C:\Users\Hao Yan\AppData\Local\Programs\Python\Python310\lib\site-packages\discord\ext\commands\core.py", line 1243, in can_run
    return await discord.utils.async_all(predicate(ctx) for predicate in predicates)
  File "C:\Users\Hao Yan\AppData\Local\Programs\Python\Python310\lib\site-packages\discord\utils.py", line 662, in async_all
    elem = await elem
  File "C:\Users\Hao Yan\AppData\Local\Programs\Python\Python310\lib\site-packages\discord\ext\commands\core.py", line 2327, in predicate
    raise NotOwner('You do not own this bot.')
discord.ext.commands.errors.NotOwner: You do not own this bot.
[2023-01-16 15:58:42] [WARNING ] discord.client: PyNaCl is not installed, voice will NOT be supported
[2023-01-16 15:58:42] [INFO    ] discord.client: logging in using static token
[2023-01-16 15:58:43] [INFO    ] discord.gateway: Shard ID None has connected to Gateway (Session ID: cf43ab39fcf4098da98ef83d3f06b8aa).
